Traceback (most recent call last):
  File "/opt/homebrew/lib/python3.11/site-packages/urllib3/response.py", line 710, in _error_catcher
    yield
  File "/opt/homebrew/lib/python3.11/site-packages/urllib3/response.py", line 1080, in read_chunked
    chunk = self._handle_chunk(amt)
            ^^^^^^^^^^^^^^^^^^^^^^^
  File "/opt/homebrew/lib/python3.11/site-packages/urllib3/response.py", line 1031, in _handle_chunk
    returned_chunk = self._fp._safe_read(self.chunk_left)  # type: ignore[union-attr]
                     ^^^^^^^^^^^^^^^^^^^^^^^^^^^^^^^^^^^^
  File "/opt/homebrew/Cellar/python@3.11/3.11.3/Frameworks/Python.framework/Versions/3.11/lib/python3.11/http/client.py", line 633, in _safe_read
    raise IncompleteRead(data, amt-len(data))
http.client.IncompleteRead: IncompleteRead(1803 bytes read, 2293 more expected)

The above exception was the direct cause of the following exception:

Traceback (most recent call last):
  File "/opt/homebrew/lib/python3.11/site-packages/requests/models.py", line 816, in generate
    yield from self.raw.stream(chunk_size, decode_content=True)
  File "/opt/homebrew/lib/python3.11/site-packages/urllib3/response.py", line 937, in stream
    yield from self.read_chunked(amt, decode_content=decode_content)
  File "/opt/homebrew/lib/python3.11/site-packages/urllib3/response.py", line 1065, in read_chunked
    with self._error_catcher():
  File "/opt/homebrew/Cellar/python@3.11/3.11.3/Frameworks/Python.framework/Versions/3.11/lib/python3.11/contextlib.py", line 155, in __exit__
    self.gen.throw(typ, value, traceback)
  File "/opt/homebrew/lib/python3.11/site-packages/urllib3/response.py", line 727, in _error_catcher
    raise ProtocolError(f"Connection broken: {e!r}", e) from e
urllib3.exceptions.ProtocolError: ('Connection broken: IncompleteRead(1803 bytes read, 2293 more expected)', IncompleteRead(1803 bytes read, 2293 more expected))

During handling of the above exception, another exception occurred:

Traceback (most recent call last):
  File "/Users/starantsov/Documents/bazaraki_parser_v2/main.py", line 11, in <module>
    changes_check(main_link,imprint_path)
  File "/Users/starantsov/Documents/bazaraki_parser_v2/changes_check.py", line 12, in changes_check
    link_array = make_full_link_array(url)
                 ^^^^^^^^^^^^^^^^^^^^^^^^^
  File "/Users/starantsov/Documents/bazaraki_parser_v2/make_full_link_array.py", line 12, in make_full_link_array
    page = get_parsed_page(url_index)
           ^^^^^^^^^^^^^^^^^^^^^^^^^^
  File "/Users/starantsov/Documents/bazaraki_parser_v2/get_parsed_page.py", line 5, in get_parsed_page
    page = requests.get(url)
           ^^^^^^^^^^^^^^^^^
  File "/opt/homebrew/lib/python3.11/site-packages/requests/api.py", line 73, in get
    return request("get", url, params=params, **kwargs)
           ^^^^^^^^^^^^^^^^^^^^^^^^^^^^^^^^^^^^^^^^^^^^
  File "/opt/homebrew/lib/python3.11/site-packages/requests/api.py", line 59, in request
    return session.request(method=method, url=url, **kwargs)
           ^^^^^^^^^^^^^^^^^^^^^^^^^^^^^^^^^^^^^^^^^^^^^^^^^
  File "/opt/homebrew/lib/python3.11/site-packages/requests/sessions.py", line 589, in request
    resp = self.send(prep, **send_kwargs)
           ^^^^^^^^^^^^^^^^^^^^^^^^^^^^^^
  File "/opt/homebrew/lib/python3.11/site-packages/requests/sessions.py", line 725, in send
    history = [resp for resp in gen]
              ^^^^^^^^^^^^^^^^^^^^^^
  File "/opt/homebrew/lib/python3.11/site-packages/requests/sessions.py", line 725, in <listcomp>
    history = [resp for resp in gen]
              ^^^^^^^^^^^^^^^^^^^^^^
  File "/opt/homebrew/lib/python3.11/site-packages/requests/sessions.py", line 266, in resolve_redirects
    resp = self.send(
           ^^^^^^^^^^
  File "/opt/homebrew/lib/python3.11/site-packages/requests/sessions.py", line 747, in send
    r.content
  File "/opt/homebrew/lib/python3.11/site-packages/requests/models.py", line 899, in content
    self._content = b"".join(self.iter_content(CONTENT_CHUNK_SIZE)) or b""
                    ^^^^^^^^^^^^^^^^^^^^^^^^^^^^^^^^^^^^^^^^^^^^^^^
  File "/opt/homebrew/lib/python3.11/site-packages/requests/models.py", line 818, in generate
    raise ChunkedEncodingError(e)
requests.exceptions.ChunkedEncodingError: ('Connection broken: IncompleteRead(1803 bytes read, 2293 more expected)', IncompleteRead(1803 bytes read, 2293 more expected))
Traceback (most recent call last):
  File "/opt/homebrew/lib/python3.11/site-packages/urllib3/connection.py", line 203, in _new_conn
    sock = connection.create_connection(
           ^^^^^^^^^^^^^^^^^^^^^^^^^^^^^
  File "/opt/homebrew/lib/python3.11/site-packages/urllib3/util/connection.py", line 60, in create_connection
    for res in socket.getaddrinfo(host, port, family, socket.SOCK_STREAM):
               ^^^^^^^^^^^^^^^^^^^^^^^^^^^^^^^^^^^^^^^^^^^^^^^^^^^^^^^^^^
  File "/opt/homebrew/Cellar/python@3.11/3.11.3/Frameworks/Python.framework/Versions/3.11/lib/python3.11/socket.py", line 962, in getaddrinfo
    for res in _socket.getaddrinfo(host, port, family, type, proto, flags):
               ^^^^^^^^^^^^^^^^^^^^^^^^^^^^^^^^^^^^^^^^^^^^^^^^^^^^^^^^^^^
socket.gaierror: [Errno 8] nodename nor servname provided, or not known

The above exception was the direct cause of the following exception:

Traceback (most recent call last):
  File "/opt/homebrew/lib/python3.11/site-packages/urllib3/connectionpool.py", line 790, in urlopen
    response = self._make_request(
               ^^^^^^^^^^^^^^^^^^^
  File "/opt/homebrew/lib/python3.11/site-packages/urllib3/connectionpool.py", line 491, in _make_request
    raise new_e
  File "/opt/homebrew/lib/python3.11/site-packages/urllib3/connectionpool.py", line 467, in _make_request
    self._validate_conn(conn)
  File "/opt/homebrew/lib/python3.11/site-packages/urllib3/connectionpool.py", line 1092, in _validate_conn
    conn.connect()
  File "/opt/homebrew/lib/python3.11/site-packages/urllib3/connection.py", line 611, in connect
    self.sock = sock = self._new_conn()
                       ^^^^^^^^^^^^^^^^
  File "/opt/homebrew/lib/python3.11/site-packages/urllib3/connection.py", line 210, in _new_conn
    raise NameResolutionError(self.host, self, e) from e
urllib3.exceptions.NameResolutionError: <urllib3.connection.HTTPSConnection object at 0x105e31a50>: Failed to resolve 'www.bazaraki.com' ([Errno 8] nodename nor servname provided, or not known)

The above exception was the direct cause of the following exception:

Traceback (most recent call last):
  File "/opt/homebrew/lib/python3.11/site-packages/requests/adapters.py", line 486, in send
    resp = conn.urlopen(
           ^^^^^^^^^^^^^
  File "/opt/homebrew/lib/python3.11/site-packages/urllib3/connectionpool.py", line 844, in urlopen
    retries = retries.increment(
              ^^^^^^^^^^^^^^^^^^
  File "/opt/homebrew/lib/python3.11/site-packages/urllib3/util/retry.py", line 515, in increment
    raise MaxRetryError(_pool, url, reason) from reason  # type: ignore[arg-type]
    ^^^^^^^^^^^^^^^^^^^^^^^^^^^^^^^^^^^^^^^^^^^^^^^^^^^
urllib3.exceptions.MaxRetryError: HTTPSConnectionPool(host='www.bazaraki.com', port=443): Max retries exceeded with url: /adv/4740481_volkswagen-tiguan-2-0l-2015/ (Caused by NameResolutionError("<urllib3.connection.HTTPSConnection object at 0x105e31a50>: Failed to resolve 'www.bazaraki.com' ([Errno 8] nodename nor servname provided, or not known)"))

During handling of the above exception, another exception occurred:

Traceback (most recent call last):
  File "/Users/starantsov/Documents/bazaraki_parser_v2/main.py", line 1, in <module>
    from changes_check import changes_check
  File "/Users/starantsov/Documents/bazaraki_parser_v2/changes_check.py", line 2, in <module>
    from log_record_add import log_record_add
  File "/Users/starantsov/Documents/bazaraki_parser_v2/log_record_add.py", line 2, in <module>
    from parse_ad_details import parse_ad_details
  File "/Users/starantsov/Documents/bazaraki_parser_v2/parse_ad_details.py", line 70, in <module>
    parse_ad_details(link)
  File "/Users/starantsov/Documents/bazaraki_parser_v2/parse_ad_details.py", line 4, in parse_ad_details
    ad_page=get_parsed_page(link)
            ^^^^^^^^^^^^^^^^^^^^^
  File "/Users/starantsov/Documents/bazaraki_parser_v2/get_parsed_page.py", line 5, in get_parsed_page
    page = requests.get(url)
           ^^^^^^^^^^^^^^^^^
  File "/opt/homebrew/lib/python3.11/site-packages/requests/api.py", line 73, in get
    return request("get", url, params=params, **kwargs)
           ^^^^^^^^^^^^^^^^^^^^^^^^^^^^^^^^^^^^^^^^^^^^
  File "/opt/homebrew/lib/python3.11/site-packages/requests/api.py", line 59, in request
    return session.request(method=method, url=url, **kwargs)
           ^^^^^^^^^^^^^^^^^^^^^^^^^^^^^^^^^^^^^^^^^^^^^^^^^
  File "/opt/homebrew/lib/python3.11/site-packages/requests/sessions.py", line 589, in request
    resp = self.send(prep, **send_kwargs)
           ^^^^^^^^^^^^^^^^^^^^^^^^^^^^^^
  File "/opt/homebrew/lib/python3.11/site-packages/requests/sessions.py", line 703, in send
    r = adapter.send(request, **kwargs)
        ^^^^^^^^^^^^^^^^^^^^^^^^^^^^^^^
  File "/opt/homebrew/lib/python3.11/site-packages/requests/adapters.py", line 519, in send
    raise ConnectionError(e, request=request)
requests.exceptions.ConnectionError: HTTPSConnectionPool(host='www.bazaraki.com', port=443): Max retries exceeded with url: /adv/4740481_volkswagen-tiguan-2-0l-2015/ (Caused by NameResolutionError("<urllib3.connection.HTTPSConnection object at 0x105e31a50>: Failed to resolve 'www.bazaraki.com' ([Errno 8] nodename nor servname provided, or not known)"))
Traceback (most recent call last):
  File "/opt/homebrew/lib/python3.11/site-packages/urllib3/connection.py", line 203, in _new_conn
    sock = connection.create_connection(
           ^^^^^^^^^^^^^^^^^^^^^^^^^^^^^
  File "/opt/homebrew/lib/python3.11/site-packages/urllib3/util/connection.py", line 60, in create_connection
    for res in socket.getaddrinfo(host, port, family, socket.SOCK_STREAM):
               ^^^^^^^^^^^^^^^^^^^^^^^^^^^^^^^^^^^^^^^^^^^^^^^^^^^^^^^^^^
  File "/opt/homebrew/Cellar/python@3.11/3.11.3/Frameworks/Python.framework/Versions/3.11/lib/python3.11/socket.py", line 962, in getaddrinfo
    for res in _socket.getaddrinfo(host, port, family, type, proto, flags):
               ^^^^^^^^^^^^^^^^^^^^^^^^^^^^^^^^^^^^^^^^^^^^^^^^^^^^^^^^^^^
socket.gaierror: [Errno 8] nodename nor servname provided, or not known

The above exception was the direct cause of the following exception:

Traceback (most recent call last):
  File "/opt/homebrew/lib/python3.11/site-packages/urllib3/connectionpool.py", line 790, in urlopen
    response = self._make_request(
               ^^^^^^^^^^^^^^^^^^^
  File "/opt/homebrew/lib/python3.11/site-packages/urllib3/connectionpool.py", line 491, in _make_request
    raise new_e
  File "/opt/homebrew/lib/python3.11/site-packages/urllib3/connectionpool.py", line 467, in _make_request
    self._validate_conn(conn)
  File "/opt/homebrew/lib/python3.11/site-packages/urllib3/connectionpool.py", line 1092, in _validate_conn
    conn.connect()
  File "/opt/homebrew/lib/python3.11/site-packages/urllib3/connection.py", line 611, in connect
    self.sock = sock = self._new_conn()
                       ^^^^^^^^^^^^^^^^
  File "/opt/homebrew/lib/python3.11/site-packages/urllib3/connection.py", line 210, in _new_conn
    raise NameResolutionError(self.host, self, e) from e
urllib3.exceptions.NameResolutionError: <urllib3.connection.HTTPSConnection object at 0x101d09a50>: Failed to resolve 'www.bazaraki.com' ([Errno 8] nodename nor servname provided, or not known)

The above exception was the direct cause of the following exception:

Traceback (most recent call last):
  File "/opt/homebrew/lib/python3.11/site-packages/requests/adapters.py", line 486, in send
    resp = conn.urlopen(
           ^^^^^^^^^^^^^
  File "/opt/homebrew/lib/python3.11/site-packages/urllib3/connectionpool.py", line 844, in urlopen
    retries = retries.increment(
              ^^^^^^^^^^^^^^^^^^
  File "/opt/homebrew/lib/python3.11/site-packages/urllib3/util/retry.py", line 515, in increment
    raise MaxRetryError(_pool, url, reason) from reason  # type: ignore[arg-type]
    ^^^^^^^^^^^^^^^^^^^^^^^^^^^^^^^^^^^^^^^^^^^^^^^^^^^
urllib3.exceptions.MaxRetryError: HTTPSConnectionPool(host='www.bazaraki.com', port=443): Max retries exceeded with url: /adv/4740481_volkswagen-tiguan-2-0l-2015/ (Caused by NameResolutionError("<urllib3.connection.HTTPSConnection object at 0x101d09a50>: Failed to resolve 'www.bazaraki.com' ([Errno 8] nodename nor servname provided, or not known)"))

During handling of the above exception, another exception occurred:

Traceback (most recent call last):
  File "/Users/starantsov/Documents/bazaraki_parser_v2/main.py", line 1, in <module>
    from changes_check import changes_check
  File "/Users/starantsov/Documents/bazaraki_parser_v2/changes_check.py", line 2, in <module>
    from log_record_add import log_record_add
  File "/Users/starantsov/Documents/bazaraki_parser_v2/log_record_add.py", line 2, in <module>
    from parse_ad_details import parse_ad_details
  File "/Users/starantsov/Documents/bazaraki_parser_v2/parse_ad_details.py", line 70, in <module>
    parse_ad_details(link)
  File "/Users/starantsov/Documents/bazaraki_parser_v2/parse_ad_details.py", line 4, in parse_ad_details
    ad_page=get_parsed_page(link)
            ^^^^^^^^^^^^^^^^^^^^^
  File "/Users/starantsov/Documents/bazaraki_parser_v2/get_parsed_page.py", line 5, in get_parsed_page
    page = requests.get(url)
           ^^^^^^^^^^^^^^^^^
  File "/opt/homebrew/lib/python3.11/site-packages/requests/api.py", line 73, in get
    return request("get", url, params=params, **kwargs)
           ^^^^^^^^^^^^^^^^^^^^^^^^^^^^^^^^^^^^^^^^^^^^
  File "/opt/homebrew/lib/python3.11/site-packages/requests/api.py", line 59, in request
    return session.request(method=method, url=url, **kwargs)
           ^^^^^^^^^^^^^^^^^^^^^^^^^^^^^^^^^^^^^^^^^^^^^^^^^
  File "/opt/homebrew/lib/python3.11/site-packages/requests/sessions.py", line 589, in request
    resp = self.send(prep, **send_kwargs)
           ^^^^^^^^^^^^^^^^^^^^^^^^^^^^^^
  File "/opt/homebrew/lib/python3.11/site-packages/requests/sessions.py", line 703, in send
    r = adapter.send(request, **kwargs)
        ^^^^^^^^^^^^^^^^^^^^^^^^^^^^^^^
  File "/opt/homebrew/lib/python3.11/site-packages/requests/adapters.py", line 519, in send
    raise ConnectionError(e, request=request)
requests.exceptions.ConnectionError: HTTPSConnectionPool(host='www.bazaraki.com', port=443): Max retries exceeded with url: /adv/4740481_volkswagen-tiguan-2-0l-2015/ (Caused by NameResolutionError("<urllib3.connection.HTTPSConnection object at 0x101d09a50>: Failed to resolve 'www.bazaraki.com' ([Errno 8] nodename nor servname provided, or not known)"))
Traceback (most recent call last):
  File "/opt/homebrew/lib/python3.11/site-packages/urllib3/connection.py", line 203, in _new_conn
    sock = connection.create_connection(
           ^^^^^^^^^^^^^^^^^^^^^^^^^^^^^
  File "/opt/homebrew/lib/python3.11/site-packages/urllib3/util/connection.py", line 60, in create_connection
    for res in socket.getaddrinfo(host, port, family, socket.SOCK_STREAM):
               ^^^^^^^^^^^^^^^^^^^^^^^^^^^^^^^^^^^^^^^^^^^^^^^^^^^^^^^^^^
  File "/opt/homebrew/Cellar/python@3.11/3.11.3/Frameworks/Python.framework/Versions/3.11/lib/python3.11/socket.py", line 962, in getaddrinfo
    for res in _socket.getaddrinfo(host, port, family, type, proto, flags):
               ^^^^^^^^^^^^^^^^^^^^^^^^^^^^^^^^^^^^^^^^^^^^^^^^^^^^^^^^^^^
socket.gaierror: [Errno 8] nodename nor servname provided, or not known

The above exception was the direct cause of the following exception:

Traceback (most recent call last):
  File "/opt/homebrew/lib/python3.11/site-packages/urllib3/connectionpool.py", line 790, in urlopen
    response = self._make_request(
               ^^^^^^^^^^^^^^^^^^^
  File "/opt/homebrew/lib/python3.11/site-packages/urllib3/connectionpool.py", line 491, in _make_request
    raise new_e
  File "/opt/homebrew/lib/python3.11/site-packages/urllib3/connectionpool.py", line 467, in _make_request
    self._validate_conn(conn)
  File "/opt/homebrew/lib/python3.11/site-packages/urllib3/connectionpool.py", line 1092, in _validate_conn
    conn.connect()
  File "/opt/homebrew/lib/python3.11/site-packages/urllib3/connection.py", line 611, in connect
    self.sock = sock = self._new_conn()
                       ^^^^^^^^^^^^^^^^
  File "/opt/homebrew/lib/python3.11/site-packages/urllib3/connection.py", line 210, in _new_conn
    raise NameResolutionError(self.host, self, e) from e
urllib3.exceptions.NameResolutionError: <urllib3.connection.HTTPSConnection object at 0x1025062d0>: Failed to resolve 'www.bazaraki.com' ([Errno 8] nodename nor servname provided, or not known)

The above exception was the direct cause of the following exception:

Traceback (most recent call last):
  File "/opt/homebrew/lib/python3.11/site-packages/requests/adapters.py", line 486, in send
    resp = conn.urlopen(
           ^^^^^^^^^^^^^
  File "/opt/homebrew/lib/python3.11/site-packages/urllib3/connectionpool.py", line 844, in urlopen
    retries = retries.increment(
              ^^^^^^^^^^^^^^^^^^
  File "/opt/homebrew/lib/python3.11/site-packages/urllib3/util/retry.py", line 515, in increment
    raise MaxRetryError(_pool, url, reason) from reason  # type: ignore[arg-type]
    ^^^^^^^^^^^^^^^^^^^^^^^^^^^^^^^^^^^^^^^^^^^^^^^^^^^
urllib3.exceptions.MaxRetryError: HTTPSConnectionPool(host='www.bazaraki.com', port=443): Max retries exceeded with url: /adv/4740481_volkswagen-tiguan-2-0l-2015/ (Caused by NameResolutionError("<urllib3.connection.HTTPSConnection object at 0x1025062d0>: Failed to resolve 'www.bazaraki.com' ([Errno 8] nodename nor servname provided, or not known)"))

During handling of the above exception, another exception occurred:

Traceback (most recent call last):
  File "/Users/starantsov/Documents/bazaraki_parser_v2/main.py", line 1, in <module>
    from changes_check import changes_check
  File "/Users/starantsov/Documents/bazaraki_parser_v2/changes_check.py", line 2, in <module>
    from log_record_add import log_record_add
  File "/Users/starantsov/Documents/bazaraki_parser_v2/log_record_add.py", line 2, in <module>
    from parse_ad_details import parse_ad_details
  File "/Users/starantsov/Documents/bazaraki_parser_v2/parse_ad_details.py", line 70, in <module>
    parse_ad_details(link)
  File "/Users/starantsov/Documents/bazaraki_parser_v2/parse_ad_details.py", line 4, in parse_ad_details
    ad_page=get_parsed_page(link)
            ^^^^^^^^^^^^^^^^^^^^^
  File "/Users/starantsov/Documents/bazaraki_parser_v2/get_parsed_page.py", line 5, in get_parsed_page
    page = requests.get(url)
           ^^^^^^^^^^^^^^^^^
  File "/opt/homebrew/lib/python3.11/site-packages/requests/api.py", line 73, in get
    return request("get", url, params=params, **kwargs)
           ^^^^^^^^^^^^^^^^^^^^^^^^^^^^^^^^^^^^^^^^^^^^
  File "/opt/homebrew/lib/python3.11/site-packages/requests/api.py", line 59, in request
    return session.request(method=method, url=url, **kwargs)
           ^^^^^^^^^^^^^^^^^^^^^^^^^^^^^^^^^^^^^^^^^^^^^^^^^
  File "/opt/homebrew/lib/python3.11/site-packages/requests/sessions.py", line 589, in request
    resp = self.send(prep, **send_kwargs)
           ^^^^^^^^^^^^^^^^^^^^^^^^^^^^^^
  File "/opt/homebrew/lib/python3.11/site-packages/requests/sessions.py", line 703, in send
    r = adapter.send(request, **kwargs)
        ^^^^^^^^^^^^^^^^^^^^^^^^^^^^^^^
  File "/opt/homebrew/lib/python3.11/site-packages/requests/adapters.py", line 519, in send
    raise ConnectionError(e, request=request)
requests.exceptions.ConnectionError: HTTPSConnectionPool(host='www.bazaraki.com', port=443): Max retries exceeded with url: /adv/4740481_volkswagen-tiguan-2-0l-2015/ (Caused by NameResolutionError("<urllib3.connection.HTTPSConnection object at 0x1025062d0>: Failed to resolve 'www.bazaraki.com' ([Errno 8] nodename nor servname provided, or not known)"))
Traceback (most recent call last):
  File "/opt/homebrew/lib/python3.11/site-packages/urllib3/connection.py", line 203, in _new_conn
    sock = connection.create_connection(
           ^^^^^^^^^^^^^^^^^^^^^^^^^^^^^
  File "/opt/homebrew/lib/python3.11/site-packages/urllib3/util/connection.py", line 60, in create_connection
    for res in socket.getaddrinfo(host, port, family, socket.SOCK_STREAM):
               ^^^^^^^^^^^^^^^^^^^^^^^^^^^^^^^^^^^^^^^^^^^^^^^^^^^^^^^^^^
  File "/opt/homebrew/Cellar/python@3.11/3.11.3/Frameworks/Python.framework/Versions/3.11/lib/python3.11/socket.py", line 962, in getaddrinfo
    for res in _socket.getaddrinfo(host, port, family, type, proto, flags):
               ^^^^^^^^^^^^^^^^^^^^^^^^^^^^^^^^^^^^^^^^^^^^^^^^^^^^^^^^^^^
socket.gaierror: [Errno 8] nodename nor servname provided, or not known

The above exception was the direct cause of the following exception:

Traceback (most recent call last):
  File "/opt/homebrew/lib/python3.11/site-packages/urllib3/connectionpool.py", line 790, in urlopen
    response = self._make_request(
               ^^^^^^^^^^^^^^^^^^^
  File "/opt/homebrew/lib/python3.11/site-packages/urllib3/connectionpool.py", line 491, in _make_request
    raise new_e
  File "/opt/homebrew/lib/python3.11/site-packages/urllib3/connectionpool.py", line 467, in _make_request
    self._validate_conn(conn)
  File "/opt/homebrew/lib/python3.11/site-packages/urllib3/connectionpool.py", line 1092, in _validate_conn
    conn.connect()
  File "/opt/homebrew/lib/python3.11/site-packages/urllib3/connection.py", line 611, in connect
    self.sock = sock = self._new_conn()
                       ^^^^^^^^^^^^^^^^
  File "/opt/homebrew/lib/python3.11/site-packages/urllib3/connection.py", line 210, in _new_conn
    raise NameResolutionError(self.host, self, e) from e
urllib3.exceptions.NameResolutionError: <urllib3.connection.HTTPSConnection object at 0x1049bd010>: Failed to resolve 'www.bazaraki.com' ([Errno 8] nodename nor servname provided, or not known)

The above exception was the direct cause of the following exception:

Traceback (most recent call last):
  File "/opt/homebrew/lib/python3.11/site-packages/requests/adapters.py", line 486, in send
    resp = conn.urlopen(
           ^^^^^^^^^^^^^
  File "/opt/homebrew/lib/python3.11/site-packages/urllib3/connectionpool.py", line 844, in urlopen
    retries = retries.increment(
              ^^^^^^^^^^^^^^^^^^
  File "/opt/homebrew/lib/python3.11/site-packages/urllib3/util/retry.py", line 515, in increment
    raise MaxRetryError(_pool, url, reason) from reason  # type: ignore[arg-type]
    ^^^^^^^^^^^^^^^^^^^^^^^^^^^^^^^^^^^^^^^^^^^^^^^^^^^
urllib3.exceptions.MaxRetryError: HTTPSConnectionPool(host='www.bazaraki.com', port=443): Max retries exceeded with url: /adv/4740481_volkswagen-tiguan-2-0l-2015/ (Caused by NameResolutionError("<urllib3.connection.HTTPSConnection object at 0x1049bd010>: Failed to resolve 'www.bazaraki.com' ([Errno 8] nodename nor servname provided, or not known)"))

During handling of the above exception, another exception occurred:

Traceback (most recent call last):
  File "/Users/starantsov/Documents/bazaraki_parser_v2/main.py", line 1, in <module>
    from changes_check import changes_check
  File "/Users/starantsov/Documents/bazaraki_parser_v2/changes_check.py", line 2, in <module>
    from log_record_add import log_record_add
  File "/Users/starantsov/Documents/bazaraki_parser_v2/log_record_add.py", line 2, in <module>
    from parse_ad_details import parse_ad_details
  File "/Users/starantsov/Documents/bazaraki_parser_v2/parse_ad_details.py", line 70, in <module>
    parse_ad_details(link)
  File "/Users/starantsov/Documents/bazaraki_parser_v2/parse_ad_details.py", line 4, in parse_ad_details
    ad_page=get_parsed_page(link)
            ^^^^^^^^^^^^^^^^^^^^^
  File "/Users/starantsov/Documents/bazaraki_parser_v2/get_parsed_page.py", line 5, in get_parsed_page
    page = requests.get(url)
           ^^^^^^^^^^^^^^^^^
  File "/opt/homebrew/lib/python3.11/site-packages/requests/api.py", line 73, in get
    return request("get", url, params=params, **kwargs)
           ^^^^^^^^^^^^^^^^^^^^^^^^^^^^^^^^^^^^^^^^^^^^
  File "/opt/homebrew/lib/python3.11/site-packages/requests/api.py", line 59, in request
    return session.request(method=method, url=url, **kwargs)
           ^^^^^^^^^^^^^^^^^^^^^^^^^^^^^^^^^^^^^^^^^^^^^^^^^
  File "/opt/homebrew/lib/python3.11/site-packages/requests/sessions.py", line 589, in request
    resp = self.send(prep, **send_kwargs)
           ^^^^^^^^^^^^^^^^^^^^^^^^^^^^^^
  File "/opt/homebrew/lib/python3.11/site-packages/requests/sessions.py", line 703, in send
    r = adapter.send(request, **kwargs)
        ^^^^^^^^^^^^^^^^^^^^^^^^^^^^^^^
  File "/opt/homebrew/lib/python3.11/site-packages/requests/adapters.py", line 519, in send
    raise ConnectionError(e, request=request)
requests.exceptions.ConnectionError: HTTPSConnectionPool(host='www.bazaraki.com', port=443): Max retries exceeded with url: /adv/4740481_volkswagen-tiguan-2-0l-2015/ (Caused by NameResolutionError("<urllib3.connection.HTTPSConnection object at 0x1049bd010>: Failed to resolve 'www.bazaraki.com' ([Errno 8] nodename nor servname provided, or not known)"))
Traceback (most recent call last):
  File "/Users/starantsov/Documents/bazaraki_parser_v2/main.py", line 11, in <module>
    changes_check(main_link,imprint_path)
  File "/Users/starantsov/Documents/bazaraki_parser_v2/changes_check.py", line 21, in changes_check
    log_record_add(link_element, log_path)
  File "/Users/starantsov/Documents/bazaraki_parser_v2/log_record_add.py", line 5, in log_record_add
    ad_details_array = parse_ad_details(link)
                       ^^^^^^^^^^^^^^^^^^^^^^
  File "/Users/starantsov/Documents/bazaraki_parser_v2/parse_ad_details.py", line 16, in parse_ad_details
    photos=ad_page.find('div', class_='announcement__images').find_all('img', class_='announcement__images-item')
           ^^^^^^^^^^^^^^^^^^^^^^^^^^^^^^^^^^^^^^^^^^^^^^^^^^^^^^^^^^^
AttributeError: 'NoneType' object has no attribute 'find_all'
Traceback (most recent call last):
  File "/Users/starantsov/Documents/bazaraki_parser_v2/main.py", line 11, in <module>
    changes_check(main_link,imprint_path)
  File "/Users/starantsov/Documents/bazaraki_parser_v2/changes_check.py", line 21, in changes_check
    log_record_add(link_element, log_path)
  File "/Users/starantsov/Documents/bazaraki_parser_v2/log_record_add.py", line 5, in log_record_add
    ad_details_array = parse_ad_details(link)
                       ^^^^^^^^^^^^^^^^^^^^^^
  File "/Users/starantsov/Documents/bazaraki_parser_v2/parse_ad_details.py", line 16, in parse_ad_details
    photos=ad_page.find('div', class_='announcement__images').find_all('img', class_='announcement__images-item')
           ^^^^^^^^^^^^^^^^^^^^^^^^^^^^^^^^^^^^^^^^^^^^^^^^^^^^^^^^^^^
AttributeError: 'NoneType' object has no attribute 'find_all'
Traceback (most recent call last):
  File "/Users/starantsov/Documents/bazaraki_parser_v2/main.py", line 11, in <module>
    changes_check(main_link,imprint_path)
  File "/Users/starantsov/Documents/bazaraki_parser_v2/changes_check.py", line 21, in changes_check
    log_record_add(link_element, log_path)
  File "/Users/starantsov/Documents/bazaraki_parser_v2/log_record_add.py", line 5, in log_record_add
    ad_details_array = parse_ad_details(link)
                       ^^^^^^^^^^^^^^^^^^^^^^
  File "/Users/starantsov/Documents/bazaraki_parser_v2/parse_ad_details.py", line 16, in parse_ad_details
    photos=ad_page.find('div', class_='announcement__images').find_all('img', class_='announcement__images-item')
           ^^^^^^^^^^^^^^^^^^^^^^^^^^^^^^^^^^^^^^^^^^^^^^^^^^^^^^^^^^^
AttributeError: 'NoneType' object has no attribute 'find_all'
Traceback (most recent call last):
  File "/Users/starantsov/Documents/bazaraki_parser_v2/main.py", line 11, in <module>
    changes_check(main_link,imprint_path)
  File "/Users/starantsov/Documents/bazaraki_parser_v2/changes_check.py", line 21, in changes_check
    log_record_add(link_element, log_path)
  File "/Users/starantsov/Documents/bazaraki_parser_v2/log_record_add.py", line 5, in log_record_add
    ad_details_array = parse_ad_details(link)
                       ^^^^^^^^^^^^^^^^^^^^^^
  File "/Users/starantsov/Documents/bazaraki_parser_v2/parse_ad_details.py", line 16, in parse_ad_details
    photos=ad_page.find('div', class_='announcement__images').find_all('img', class_='announcement__images-item')
           ^^^^^^^^^^^^^^^^^^^^^^^^^^^^^^^^^^^^^^^^^^^^^^^^^^^^^^^^^^^
AttributeError: 'NoneType' object has no attribute 'find_all'
Traceback (most recent call last):
  File "/Users/starantsov/Documents/bazaraki_parser_v2/main.py", line 11, in <module>
    changes_check(main_link,imprint_path)
  File "/Users/starantsov/Documents/bazaraki_parser_v2/changes_check.py", line 21, in changes_check
    log_record_add(link_element, log_path)
  File "/Users/starantsov/Documents/bazaraki_parser_v2/log_record_add.py", line 5, in log_record_add
    ad_details_array = parse_ad_details(link)
                       ^^^^^^^^^^^^^^^^^^^^^^
  File "/Users/starantsov/Documents/bazaraki_parser_v2/parse_ad_details.py", line 16, in parse_ad_details
    photos=ad_page.find('div', class_='announcement__images').find_all('img', class_='announcement__images-item')
           ^^^^^^^^^^^^^^^^^^^^^^^^^^^^^^^^^^^^^^^^^^^^^^^^^^^^^^^^^^^
AttributeError: 'NoneType' object has no attribute 'find_all'
